<?xml version="1.0"?>
<robot name="simple_robot_arm">

  <!-- Base Link -->
  <link name="base_link">
    <visual>
      <geometry>
        <cylinder length="0.05" radius="0.1"/>
      </geometry>
      <material name="grey">
        <color rgba="0.5 0.5 0.5 1"/>
      </material>
    </visual>
    <collision>
      <geometry>
        <cylinder length="0.05" radius="0.1"/>
      </geometry>
    </collision>
    <inertial>
      <mass value="1.0"/>
      <inertia ixx="0.01" ixy="0" ixz="0" iyy="0.01" iyz="0" izz="0.01"/>
    </inertial>
  </link>

  <!-- Shoulder Link -->
  <link name="shoulder_link">
    <visual>
      <geometry>
        <box size="0.1 0.1 0.4"/>
      </geometry>
      <material name="blue">
        <color rgba="0.1 0.1 0.8 1"/>
      </material>
    </visual>
    <collision>
      <geometry>
        <box size="0.1 0.1 0.4"/>
      </geometry>
    </collision>
    <inertial>
      <mass value="0.5"/>
      <inertia ixx="0.001" ixy="0" ixz="0" iyy="0.001" iyz="0" izz="0.001"/>
    </inertial>
  </link>

  <!-- Shoulder Joint -->
  <joint name="shoulder_joint" type="revolute">
    <parent link="base_link"/>
    <child link="shoulder_link"/>
    <origin xyz="0 0 0.025" rpy="0 0 0"/>
    <axis xyz="0 1 0"/>
    <limit lower="-1.57" upper="1.57" effort="10.0" velocity="1.0"/>
  </joint>

  <!-- Elbow Link -->
  <link name="elbow_link">
    <visual>
      <geometry>
        <box size="0.1 0.1 0.3"/>
      </geometry>
      <material name="grey"/>
    </visual>
    <collision>
      <geometry>
        <box size="0.1 0.1 0.3"/>
      </geometry>
    </collision>
    <inertial>
      <mass value="0.3"/>
      <inertia ixx="0.001" ixy="0" ixz="0" iyy="0.001" iyz="0" izz="0.001"/>
    </inertial>
  </link>

  <!-- Elbow Joint -->
  <joint name="elbow_joint" type="revolute">
    <parent link="shoulder_link"/>
    <child link="elbow_link"/>
    <origin xyz="0 0 0.2" rpy="0 0 0"/>
    <axis xyz="0 1 0"/>
    <limit lower="-1.57" upper="1.57" effort="10.0" velocity="1.0"/>
  </joint>

  <!-- Wrist Link -->
  <link name="wrist_link">
    <visual>
      <geometry>
        <box size="0.08 0.08 0.08"/>
      </geometry>
      <material name="blue"/>
    </visual>
    <collision>
      <geometry>
        <box size="0.08 0.08 0.08"/>
      </geometry>
    </collision>
    <inertial>
      <mass value="0.1"/>
      <inertia ixx="0.0001" ixy="0" ixz="0" iyy="0.0001" iyz="0" izz="0.0001"/>
    </inertial>
  </link>

  <!-- Wrist Joint -->
  <joint name="wrist_joint" type="revolute">
    <parent link="elbow_link"/>
    <child link="wrist_link"/>
    <origin xyz="0 0 0.15" rpy="0 0 0"/>
    <axis xyz="0 0 1"/>
    <limit lower="-1.57" upper="1.57" effort="5.0" velocity="1.5"/>
  </joint>

</robot>
